/home/mohammed/Code/Testing/.venv/bin/python /home/mohammed/Code/Testing/dashboard.py 
Traceback (most recent call last):
  File "/home/mohammed/Code/Testing/.venv/lib/python3.12/site-packages/pandas/core/indexes/base.py", line 3805, in get_loc
    return self._engine.get_loc(casted_key)
           ^^^^^^^^^^^^^^^^^^^^^^^^^^^^^^^^
  File "index.pyx", line 167, in pandas._libs.index.IndexEngine.get_loc
  File "index.pyx", line 196, in pandas._libs.index.IndexEngine.get_loc
  File "pandas/_libs/hashtable_class_helper.pxi", line 7081, in pandas._libs.hashtable.PyObjectHashTable.get_item
  File "pandas/_libs/hashtable_class_helper.pxi", line 7089, in pandas._libs.hashtable.PyObjectHashTable.get_item
KeyError: 'T2'

The above exception was the direct cause of the following exception:

Traceback (most recent call last):
  File "/home/mohammed/Code/Testing/dashboard.py", line 110, in <module>
    df = load_data(initial_date)
         ^^^^^^^^^^^^^^^^^^^^^^^
  File "/home/mohammed/Code/Testing/dashboard.py", line 89, in load_data
    df['T2'] = pd.to_datetime(df['T2'])
                              ~~^^^^^^
  File "/home/mohammed/Code/Testing/.venv/lib/python3.12/site-packages/pandas/core/frame.py", line 4102, in __getitem__
    indexer = self.columns.get_loc(key)
              ^^^^^^^^^^^^^^^^^^^^^^^^^
  File "/home/mohammed/Code/Testing/.venv/lib/python3.12/site-packages/pandas/core/indexes/base.py", line 3812, in get_loc
    raise KeyError(key) from err
KeyError: 'T2'
